<?xml version="1.0" encoding="utf-8"?>
<!-- This URDF was automatically created by SolidWorks to URDF Exporter! Originally created by Stephen Brawner (brawner@gmail.com) 
     Commit Version: 1.6.0-4-g7f85cfe  Build Version: 1.6.7995.38578
     For more information, please see http://wiki.ros.org/sw_urdf_exporter -->
<robot
  name="R1">
  <link
    name="base_link">
    <inertial>
      <origin
        xyz="-0.0030503 -9.6245E-05 0.14087"
        rpy="0 0 0" />
      <mass
        value="68.732" />
      <inertia
        ixx="1.5812"
        ixy="-1.0627E-05"
        ixz="0.053601"
        iyy="1.4648"
        iyz="5.7052E-06"
        izz="2.835" />
    </inertial>
    <visual>
      <origin
        xyz="0 0 0"
        rpy="0 0 0" />
      <geometry>
        <mesh
          filename="package://R1/meshes/base_link.STL" />
      </geometry>
      <material
        name="">
        <color
          rgba="0.82353 0.82353 1 1" />
      </material>
    </visual>
    <collision>
      <origin
        xyz="0 0 0"
        rpy="0 0 0" />
      <geometry>
        <mesh
          filename="package://R1/meshes/base_link.STL" />
      </geometry>
    </collision>
  </link>
  <link
    name="servo_link1">
    <inertial>
      <origin
        xyz="7.5341E-06 -0.0035676 -0.04821"
        rpy="0 0 0" />
      <mass
        value="1.0" />
      <inertia
        ixx="0.00021869"
        ixy="-3.4649E-09"
        ixz="2.6493E-09"
        iyy="0.00032528"
        iyz="2.5507E-07"
        izz="0.00015773" />
    </inertial>
    <visual>
      <origin
        xyz="0 0 0"
        rpy="0 0 0" />
      <geometry>
        <mesh
          filename="package://R1/meshes/servo_link1.STL" />
      </geometry>
      <material
        name="">
        <color
          rgba="0.82353 0.82353 1 1" />
      </material>
    </visual>
    <collision>
      <origin
        xyz="0 0 0"
        rpy="0 0 0" />
      <geometry>
        <mesh
          filename="package://R1/meshes/servo_link1.STL" />
      </geometry>
    </collision>
  </link>
  <joint
    name="servo_joint1"
    type="revolute">
    <origin
      xyz="0.21516 0.28001 0.116"
      rpy="0 0 0" />
    <parent
      link="base_link" />
    <child
      link="servo_link1" />
    <axis
      xyz="0 0 1" />
    <limit
      lower="-1.5708"
      upper="1.5708"
      effort="44"
      velocity="3.1416" />
  </joint>
  <link
    name="wheel_link1">
    <inertial>
      <origin
        xyz="-2.0533E-09 -6.2367E-09 -0.0277"
        rpy="0 0 0" />
      <mass
        value="2.2" />
      <inertia
        ixx="0.0012628"
        ixy="-5.7971E-09"
        ixz="-7.3456E-12"
        iyy="0.0012628"
        iyz="-1.6082E-11"
        izz="0.0020893" />
    </inertial>
    <visual>
      <origin
        xyz="0 0 0"
        rpy="0 0 0" />
      <geometry>
        <mesh
          filename="package://R1/meshes/wheel_link1.STL" />
      </geometry>
      <material
        name="">
        <color
          rgba="0.82353 0.82353 1 1" />
      </material>
    </visual>
    <collision>
      <origin
        xyz="0 0 0"
        rpy="0 0 0" />
      <geometry>
        <mesh
          filename="package://R1/meshes/wheel_link1.STL" />
      </geometry>
    </collision>
  </link>
  <joint
    name="wheel_joint1"
    type="continuous">
    <origin
      xyz="0 0.027694 -0.08765"
      rpy="-1.5708 0 0" />
    <parent
      link="servo_link1" />
    <child
      link="wheel_link1" />
    <axis
      xyz="0 0 1" />
  </joint>
  <link
    name="servo_link2">
    <inertial>
      <origin
        xyz="7.5219E-06 -0.0035675 -0.04821"
        rpy="0 0 0" />
      <mass
        value="1.0" />
      <inertia
        ixx="0.0002187"
        ixy="-3.4594E-09"
        ixz="2.4969E-09"
        iyy="0.00032528"
        iyz="2.5522E-07"
        izz="0.00015773" />
    </inertial>
    <visual>
      <origin
        xyz="0 0 0"
        rpy="0 0 0" />
      <geometry>
        <mesh
          filename="package://R1/meshes/servo_link2.STL" />
      </geometry>
      <material
        name="">
        <color
          rgba="0.82353 0.82353 1 1" />
      </material>
    </visual>
    <collision>
      <origin
        xyz="0 0 0"
        rpy="0 0 0" />
      <geometry>
        <mesh
          filename="package://R1/meshes/servo_link2.STL" />
      </geometry>
    </collision>
  </link>
  <joint
    name="servo_joint2"
    type="revolute">
    <origin
      xyz="0.21516 -0.27999 0.116"
      rpy="0 0 0" />
    <parent
      link="base_link" />
    <child
      link="servo_link2" />
    <axis
      xyz="0 0 1" />
    <limit
      lower="-1.5708"
      upper="1.5708"
      effort="44"
      velocity="3.1416" />
  </joint>
  <link
    name="wheel_link2">
    <inertial>
      <origin
        xyz="-2.0528E-09 -6.2367E-09 -0.0277"
        rpy="0 0 0" />
      <mass
        value="2.2" />
      <inertia
        ixx="0.0012628"
        ixy="-5.7971E-09"
        ixz="-7.3429E-12"
        iyy="0.0012628"
        iyz="-1.6081E-11"
        izz="0.0020893" />
    </inertial>
    <visual>
      <origin
        xyz="0 0 0"
        rpy="0 0 0" />
      <geometry>
        <mesh
          filename="package://R1/meshes/wheel_link2.STL" />
      </geometry>
      <material
        name="">
        <color
          rgba="0.82353 0.82353 1 1" />
      </material>
    </visual>
    <collision>
      <origin
        xyz="0 0 0"
        rpy="0 0 0" />
      <geometry>
        <mesh
          filename="package://R1/meshes/wheel_link2.STL" />
      </geometry>
    </collision>
  </link>
  <joint
    name="wheel_joint2"
    type="continuous">
    <origin
      xyz="0 0.0276943179214421 -0.0876499639638649"
      rpy="-1.5707948453441 0 0" />
    <parent
      link="servo_link2" />
    <child
      link="wheel_link2" />
    <axis
      xyz="0 0 1" />
  </joint>
  <link
    name="servo_link3">
    <inertial>
      <origin
        xyz="-7.163E-06 0.0035641 -0.04821"
        rpy="0 0 0" />
      <mass
        value="1.0" />
      <inertia
        ixx="0.0002187"
        ixy="-3.3419E-09"
        ixz="-2.0956E-09"
        iyy="0.00032528"
        iyz="-2.5463E-07"
        izz="0.00015773" />
    </inertial>
    <visual>
      <origin
        xyz="0 0 0"
        rpy="0 0 0" />
      <geometry>
        <mesh
          filename="package://R1/meshes/servo_link3.STL" />
      </geometry>
      <material
        name="">
        <color
          rgba="0.82353 0.82353 1 1" />
      </material>
    </visual>
    <collision>
      <origin
        xyz="0 0 0"
        rpy="0 0 0" />
      <geometry>
        <mesh
          filename="package://R1/meshes/servo_link3.STL" />
      </geometry>
    </collision>
  </link>
  <joint
    name="servo_joint3"
    type="revolute">
    <origin
      xyz="-0.28085 0 0.116"
      rpy="0 0 0" />
    <parent
      link="base_link" />
    <child
      link="servo_link3" />
    <axis
      xyz="0 0 1" />
    <limit
      lower="-1.5708"
      upper="1.5708"
      effort="44"
      velocity="3.1416" />
  </joint>
  <link
    name="wheel_link3">
    <inertial>
      <origin
        xyz="7.3358E-09 4.0895E-09 -0.0277"
        rpy="0 0 0" />
      <mass
        value="2.0" />
      <inertia
        ixx="0.0012628"
        ixy="-5.7894E-09"
        ixz="2.5267E-15"
        iyy="0.0012628"
        iyz="1.9268E-11"
        izz="0.0020893" />
    </inertial>
    <visual>
      <origin
        xyz="0 0 0"
        rpy="0 0 0" />
      <geometry>
        <mesh
          filename="package://R1/meshes/wheel_link3.STL" />
      </geometry>
      <material
        name="">
        <color
          rgba="0.82353 0.82353 1 1" />
      </material>
    </visual>
    <collision>
      <origin
        xyz="0 0 0"
        rpy="0 0 0" />
      <geometry>
        <mesh
          filename="package://R1/meshes/wheel_link3.STL" />
      </geometry>
    </collision>
  </link>
  <joint
    name="wheel_joint3"
    type="continuous">
    <origin
      xyz="0 0.027702 -0.08765"
      rpy="-1.5708 0 0" />
    <parent
      link="servo_link3" />
    <child
      link="wheel_link3" />
    <axis
      xyz="0 0 1" />
  </joint>
  <link
    name="torso_link1">
    <inertial>
      <origin
        xyz="0.00065636 -0.23142 0.0032247"
        rpy="0 0 0" />
      <mass
        value="10.0" />
      <inertia
        ixx="0.30931"
        ixy="0.00017473"
        ixz="7.7895E-06"
        iyy="0.0081222"
        iyz="-0.00013763"
        izz="0.30736" />
    </inertial>
    <visual>
      <origin
        xyz="0 0 0"
        rpy="0 0 0" />
      <geometry>
        <mesh
          filename="package://R1/meshes/torso_link1.STL" />
      </geometry>
      <material
        name="">
        <color
          rgba="0.82353 0.82353 1 1" />
      </material>
    </visual>
    <collision>
      <origin
        xyz="0 0 0"
        rpy="0 0 0" />
      <geometry>
        <mesh
          filename="package://R1/meshes/torso_link1.STL" />
      </geometry>
    </collision>
  </link>
  <joint
    name="torso_joint1"
    type="revolute">
    <origin
      xyz="-0.032845 0 0.301"
      rpy="-1.5708 0 0" />
    <parent
      link="base_link" />
    <child
      link="torso_link1" />
    <axis
      xyz="0 0 1" />
    <limit
      lower="-1.1345"
      upper="1.8326"
      effort="0"
      velocity="0" />
  </joint>
  <link
    name="torso_link2">
    <inertial>
      <origin
        xyz="0.0052517 -0.15711 0.014411"
        rpy="0 0 0" />
      <mass
        value="3.4" />
      <inertia
        ixx="0.026081"
        ixy="-0.00024541"
        ixz="-3.342E-07"
        iyy="0.0018515"
        iyz="-3.8476E-07"
        izz="0.027574" />
    </inertial>
    <visual>
      <origin
        xyz="0 0 0"
        rpy="0 0 0" />
      <geometry>
        <mesh
          filename="package://R1/meshes/torso_link2.STL" />
      </geometry>
      <material
        name="">
        <color
          rgba="0.82353 0.82353 1 1" />
      </material>
    </visual>
    <collision>
      <origin
        xyz="0 0 0"
        rpy="0 0 0" />
      <geometry>
        <mesh
          filename="package://R1/meshes/torso_link2.STL" />
      </geometry>
    </collision>
  </link>
  <joint
    name="torso_joint2"
    type="revolute">
    <origin
      xyz="0 -0.4 0"
      rpy="0 0 0" />
    <parent
      link="torso_link1" />
    <child
      link="torso_link2" />
    <axis
      xyz="0 0 1" />
    <limit
      lower="-2.7925"
      upper="2.5307"
      effort="0"
      velocity="0" />
  </joint>
  <link
    name="torso_link3">
    <inertial>
      <origin
        xyz="-7.8458E-08 -0.031308 -0.00018966"
        rpy="0 0 0" />
      <mass
        value="5.5" />
      <inertia
        ixx="0.0035869"
        ixy="-5.9704E-10"
        ixz="-4.4385E-10"
        iyy="0.0036236"
        iyz="-0.00010486"
        izz="0.0043819" />
    </inertial>
    <visual>
      <origin
        xyz="0 0 0"
        rpy="0 0 0" />
      <geometry>
        <mesh
          filename="package://R1/meshes/torso_link3.STL" />
      </geometry>
      <material
        name="">
        <color
          rgba="0.79216 0.81961 0.93333 1" />
      </material>
    </visual>
    <collision>
      <origin
        xyz="0 0 0"
        rpy="0 0 0" />
      <geometry>
        <mesh
          filename="package://R1/meshes/torso_link3.STL" />
      </geometry>
    </collision>
  </link>
  <joint
    name="torso_joint3"
    type="revolute">
    <origin
      xyz="0 -0.3 0"
      rpy="0 0 0" />
    <parent
      link="torso_link2" />
    <child
      link="torso_link3" />
    <axis
      xyz="0 0 1" />
    <limit
      lower="-2.0944"
      upper="1.8326"
      effort="0"
      velocity="0" />
  </joint>
  <link
    name="torso_link4">
    <inertial>
      <origin
        xyz="-0.0025153 3.1179E-07 0.35873"
        rpy="0 0 0" />
      <mass
        value="16.778" />
      <inertia
        ixx="0.015187"
        ixy="7.199E-08"
        ixz="0.00054617"
        iyy="0.013478"
        iyz="-2.0225E-07"
        izz="0.017316" />
    </inertial>
    <visual>
      <origin
        xyz="0 0 0"
        rpy="0 0 0" />
      <geometry>
        <mesh
          filename="package://R1/meshes/torso_link4.STL" />
      </geometry>
      <material
        name="">
        <color
          rgba="0.79216 0.81961 0.93333 1" />
      </material>
    </visual>
    <collision>
      <origin
        xyz="0 0 0"
        rpy="0 0 0" />
      <geometry>
        <mesh
          filename="package://R1/meshes/torso_link4.STL" />
      </geometry>
    </collision>
  </link>
  <joint
    name="torso_joint4"
    type="revolute">
    <origin
      xyz="0 -0.12474 0"
      rpy="1.5708 0 0" />
    <parent
      link="torso_link3" />
    <child
      link="torso_link4" />
    <axis
      xyz="0 0 1" />
    <limit
      lower="-3.0543"
      upper="3.0543"
      effort="0"
      velocity="0" />
  </joint>
  <link
    name="zed_link">
    <inertial>
      <origin
        xyz="-0.070413 -2.7792E-07 -0.015905"
        rpy="0 0 0" />
      <mass
        value="3.3094" />
      <inertia
        ixx="0.012229"
        ixy="-1.333E-08"
        ixz="-0.00028961"
        iyy="0.010375"
        iyz="1.8965E-07"
        izz="0.014618" />
    </inertial>
    <visual>
      <origin
        xyz="0 0 0"
        rpy="0 0 0" />
      <geometry>
        <mesh
          filename="package://R1/meshes/zed_link.STL" />
      </geometry>
      <material
        name="">
        <color
          rgba="0.81176 0.84314 0.9098 1" />
      </material>
    </visual>
    <collision>
      <origin
        xyz="0 0 0"
        rpy="0 0 0" />
      <geometry>
        <mesh
          filename="package://R1/meshes/zed_link.STL" />
      </geometry>
    </collision>
  </link>
  <joint
    name="zed_axis"
    type="fixed">
    <origin
      xyz="0.06739 0 0.4753"
      rpy="0 0.34906 0" />
    <parent
      link="torso_link4" />
    <child
      link="zed_link" />
    <axis
      xyz="0 0 0" />
  </joint>
  <link
    name="left_arm_link1">
    <inertial>
      <origin
        xyz="0.0020734 0.00846 0.19171"
        rpy="0 0 0" />
      <mass
        value="1.319" />
      <inertia
        ixx="0.00058101"
        ixy="7.5672E-09"
        ixz="2.9207E-08"
        iyy="0.00070857"
        iyz="8.5639E-07"
        izz="0.00044583" />
    </inertial>
    <visual>
      <origin
        xyz="0 0 0"
        rpy="0 0 0" />
      <geometry>
        <mesh
          filename="package://R1/meshes/left_arm_link1.STL" />
      </geometry>
      <material
        name="">
        <color
          rgba="0.79216 0.81961 0.93333 1" />
      </material>
    </visual>
    <collision>
      <origin
        xyz="0 0 0"
        rpy="0 0 0" />
      <geometry>
        <mesh
          filename="package://R1/meshes/left_arm_link1.STL" />
      </geometry>
    </collision>
  </link>
  <joint
    name="left_arm_joint1"
    type="revolute">
    <origin
      xyz="-0.00033786 0.13608 0.27773"
      rpy="-1.5708 0 0" />
    <parent
      link="torso_link4" />
    <child
      link="left_arm_link1" />
    <axis
      xyz="0 0 1" />
    <limit
      lower="-2.8798"
      upper="2.8798"
      effort="40"
      velocity="20.944" />
  </joint>
  <link
    name="left_arm_link2">
    <inertial>
      <origin
        xyz="-0.23622 -0.016352 0.00013272"
        rpy="0 0 0" />
      <mass
        value="1.3" />
      <inertia
        ixx="0.00060638"
        ixy="0.000041817"
        ixz="-0.00014956"
        iyy="0.0075936"
        iyz="8.0916E-06"
        izz="0.0075712" />
    </inertial>
    <visual>
      <origin
        xyz="0 0 0"
        rpy="0 0 0" />
      <geometry>
        <mesh
          filename="package://R1/meshes/left_arm_link2.STL" />
      </geometry>
      <material
        name="">
        <color
          rgba="0.79216 0.81961 0.93333 1" />
      </material>
    </visual>
    <collision>
      <origin
        xyz="0 0 0"
        rpy="0 0 0" />
      <geometry>
        <mesh
          filename="package://R1/meshes/left_arm_link2.STL" />
      </geometry>
    </collision>
  </link>
  <joint
    name="left_arm_joint2"
    type="revolute">
    <origin
      xyz="0 0 0.11185"
      rpy="-1.5708 0 0" />
    <parent
      link="left_arm_link1" />
    <child
      link="left_arm_link2" />
    <axis
      xyz="0 0 1" />
    <limit
      lower="0"
      upper="3.2289"
      effort="40"
      velocity="20.944" />
  </joint>
  <link
    name="left_arm_link3">
    <inertial>
      <origin
        xyz="0.045114 -0.054616 0.00045585"
        rpy="0 0 0" />
      <mass
        value="0.818" />
      <inertia
        ixx="0.00060107"
        ixy="0.00022467"
        ixz="7.1198E-06"
        iyy="0.0013959"
        iyz="-9.7504E-06"
        izz="0.0015027" />
    </inertial>
    <visual>
      <origin
        xyz="0 0 0"
        rpy="0 0 0" />
      <geometry>
        <mesh
          filename="package://R1/meshes/left_arm_link3.STL" />
      </geometry>
      <material
        name="">
        <color
          rgba="0.79216 0.81961 0.93333 1" />
      </material>
    </visual>
    <collision>
      <origin
        xyz="0 0 0"
        rpy="0 0 0" />
      <geometry>
        <mesh
          filename="package://R1/meshes/left_arm_link3.STL" />
      </geometry>
    </collision>
  </link>
  <joint
    name="left_arm_joint3"
    type="revolute">
    <origin
      xyz="-0.34928 -0.019999 0"
      rpy="0 0 0" />
    <parent
      link="left_arm_link2" />
    <child
      link="left_arm_link3" />
    <axis
      xyz="0 0 1" />
    <limit
      lower="-3.3161"
      upper="0"
      effort="27"
      velocity="7.5398" />
  </joint>
  <link
    name="left_arm_link4">
    <inertial>
      <origin
        xyz="8.1603E-07 -0.0023773 0.24285"
        rpy="0 0 0" />
      <mass
        value="0.816" />
      <inertia
        ixx="9.7044E-05"
        ixy="-5.3698E-09"
        ixz="-2.2378E-09"
        iyy="0.00010174"
        iyz="8.2619E-07"
        izz="8.45E-05" />
    </inertial>
    <visual>
      <origin
        xyz="0 0 0"
        rpy="0 0 0" />
      <geometry>
        <mesh
          filename="package://R1/meshes/left_arm_link4.STL" />
      </geometry>
      <material
        name="">
        <color
          rgba="1 1 1 1" />
      </material>
    </visual>
    <collision>
      <origin
        xyz="0 0 0"
        rpy="0 0 0" />
      <geometry>
        <mesh
          filename="package://R1/meshes/left_arm_link4.STL" />
      </geometry>
    </collision>
  </link>
  <joint
    name="left_arm_joint4"
    type="revolute">
    <origin
      xyz="0.02735 -0.069767 0"
      rpy="-3.1416 1.5708 3.1416" />
    <parent
      link="left_arm_link3" />
    <child
      link="left_arm_link4" />
    <axis
      xyz="0 0 1" />
    <limit
      lower="-2.8798"
      upper="2.8798"
      effort="7"
      velocity="25.133" />
  </joint>
  <link
    name="left_arm_link5">
    <inertial>
      <origin
        xyz="0.054309 3.4828E-05 0.0011809"
        rpy="0 0 0" />
      <mass
        value="0.801" />
      <inertia
        ixx="8.3999E-05"
        ixy="3.6184E-08"
        ixz="1.6234E-05"
        iyy="0.00011332"
        iyz="-9.2707E-08"
        izz="9.8499E-05" />
    </inertial>
    <visual>
      <origin
        xyz="0 0 0"
        rpy="0 0 0" />
      <geometry>
        <mesh
          filename="package://R1/meshes/left_arm_link5.STL" />
      </geometry>
      <material
        name="">
        <color
          rgba="1 1 1 1" />
      </material>
    </visual>
    <collision>
      <origin
        xyz="0 0 0"
        rpy="0 0 0" />
      <geometry>
        <mesh
          filename="package://R1/meshes/left_arm_link5.STL" />
      </geometry>
    </collision>
  </link>
  <joint
    name="left_arm_joint5"
    type="revolute">
    <origin
      xyz="0 -0.0025 0.2463"
      rpy="1.5708 -1.5703 0.0077846" />
    <parent
      link="left_arm_link4" />
    <child
      link="left_arm_link5" />
    <axis
      xyz="0 0 1" />
    <limit
      lower="-1.6581"
      upper="1.6581"
      effort="7"
      velocity="25.133" />
  </joint>
  <link
    name="left_arm_link6">
    <inertial>
      <origin
        xyz="-1.4611E-07 6.6949E-08 -0.031107"
        rpy="0 0 0" />
      <mass
        value="0.465" />
      <inertia
        ixx="0.00016512"
        ixy="8.1954E-08"
        ixz="-5.3428E-10"
        iyy="9.8637E-05"
        iyz="-2.3917E-10"
        izz="0.00017588" />
    </inertial>
    <visual>
      <origin
        xyz="0 0 0"
        rpy="0 0 0" />
      <geometry>
        <mesh
          filename="package://R1/meshes/left_arm_link6.STL" />
      </geometry>
      <material
        name="">
        <color
          rgba="0.82353 0.82353 1 1" />
      </material>
    </visual>
    <collision>
      <origin
        xyz="0 0 0"
        rpy="0 0 0" />
      <geometry>
        <mesh
          filename="package://R1/meshes/left_arm_link6.STL" />
      </geometry>
    </collision>
  </link>
  <joint
    name="left_arm_joint6"
    type="revolute">
    <origin
      xyz="0.16215 6.8925E-05 -0.0024999"
      rpy="-1.5708 -0.0077846 -1.5702" />
    <parent
      link="left_arm_link5" />
    <child
      link="left_arm_link6" />
    <axis
      xyz="0 0 1" />
    <limit
      lower="-2.8798"
      upper="2.8798"
      effort="7"
      velocity="25.133" />
  </joint>
  <link
    name="left_realsense_link">
    <inertial>
      <origin
        xyz="-0.017353 -0.022126 -0.0061733"
        rpy="0 0 0" />
      <mass
        value="0.042603" />
      <inertia
        ixx="2.5513E-05"
        ixy="-1.2897E-06"
        ixz="1.4177E-06"
        iyy="6.9283E-06"
        iyz="2.5458E-06"
        izz="2.3318E-05" />
    </inertial>
    <visual>
      <origin
        xyz="0 0 0"
        rpy="0 0 0" />
      <geometry>
        <mesh
          filename="package://R1/meshes/left_realsense_link.STL" />
      </geometry>
      <material
        name="">
        <color
          rgba="0.8 0.8 0.8 1" />
      </material>
    </visual>
    <collision>
      <origin
        xyz="0 0 0"
        rpy="0 0 0" />
      <geometry>
        <mesh
          filename="package://R1/meshes/left_realsense_link.STL" />
      </geometry>
    </collision>
  </link>
  <joint
    name="left_realsense_axis"
    type="fixed">
    <origin
      xyz="0.050549 -0.0021066 -0.0051314"
      rpy="-0.0070534 -1.1345 -3.1338" />
    <parent
      link="left_arm_link6" />
    <child
      link="left_realsense_link" />
    <axis
      xyz="0 0 0" />
  </joint>
  <link
    name="left_gripper_link1">
    <inertial>
      <origin
        xyz="-0.019586 -0.0055507 -0.015071"
        rpy="0 0 0" />
      <mass
        value="0.057" />
      <inertia
        ixx="2.4057E-06"
        ixy="-5.033E-08"
        ixz="3.9941E-07"
        iyy="6.4838E-06"
        iyz="-6.7746E-08"
        izz="5.7118E-06" />
    </inertial>
    <visual>
      <origin
        xyz="0 0 0"
        rpy="0 0 0" />
      <geometry>
        <mesh
          filename="package://R1/meshes/left_gripper_link1.STL" />
      </geometry>
      <material
        name="">
        <color
          rgba="0.82353 0.82353 1 1" />
      </material>
    </visual>
    <collision>
      <origin
        xyz="0 0 0"
        rpy="0 0 0" />
      <geometry>
        <mesh
          filename="package://R1/meshes/left_gripper_link1.STL" />
      </geometry>
    </collision>
  </link>
  <joint
    name="left_gripper_axis1"
    type="prismatic">
    <origin
      xyz="0.00012069 -0.013453 0.03689"
      rpy="1.5745 -1.5702 0.0041033" />
    <parent
      link="left_arm_link6" />
    <child
      link="left_gripper_link1" />
    <axis
      xyz="0 0 1" />
    <limit
      lower="0"
      upper="0.05"
      effort="100"
      velocity="0.25" />
  </joint>
  <link
    name="left_gripper_link2">
    <inertial>
      <origin
        xyz="-0.019593 -0.0055293 -0.015071"
        rpy="0 0 0" />
      <mass
        value="0.057" />
      <inertia
        ixx="2.4056E-06"
        ixy="-4.5884E-08"
        ixz="3.9934E-07"
        iyy="6.4839E-06"
        iyz="-6.8181E-08"
        izz="5.7118E-06" />
    </inertial>
    <visual>
      <origin
        xyz="0 0 0"
        rpy="0 0 0" />
      <geometry>
        <mesh
          filename="package://R1/meshes/left_gripper_link2.STL" />
      </geometry>
      <material
        name="">
        <color
          rgba="0.82353 0.82353 1 1" />
      </material>
    </visual>
    <collision>
      <origin
        xyz="0 0 0"
        rpy="0 0 0" />
      <geometry>
        <mesh
          filename="package://R1/meshes/left_gripper_link2.STL" />
      </geometry>
    </collision>
  </link>
  <joint
    name="left_gripper_axis2"
    type="prismatic">
    <origin
      xyz="-0.00012054 0.013453 0.03689"
      rpy="-1.5671 -1.5702 0.0041033" />
    <parent
      link="left_arm_link6" />
    <child
      link="left_gripper_link2" />
    <axis
      xyz="0 0 1" />
    <limit
      lower="0"
      upper="0.05"
      effort="100"
      velocity="0.25" />
  </joint>
  <link
    name="right_arm_link1">
    <inertial>
      <origin
        xyz="0.0020139 0.0089421 0.19171"
        rpy="0 0 0" />
      <mass
        value="1.319" />
      <inertia
        ixx="0.00058101"
        ixy="-7.5672E-09"
        ixz="-2.9207E-08"
        iyy="0.00070857"
        iyz="8.5639E-07"
        izz="0.00044583" />
    </inertial>
    <visual>
      <origin
        xyz="0 0 0"
        rpy="0 0 0" />
      <geometry>
        <mesh
          filename="package://R1/meshes/right_arm_link1.STL" />
      </geometry>
      <material
        name="">
        <color
          rgba="0.79216 0.81961 0.93333 1" />
      </material>
    </visual>
    <collision>
      <origin
        xyz="0 0 0"
        rpy="0 0 0" />
      <geometry>
        <mesh
          filename="package://R1/meshes/right_arm_link1.STL" />
      </geometry>
    </collision>
  </link>
  <joint
    name="right_arm_joint1"
    type="revolute">
    <origin
      xyz="-0.0003367 -0.13609 0.27773"
      rpy="1.5786 -0.00054698 0" />
    <parent
      link="torso_link4" />
    <child
      link="right_arm_link1" />
    <axis
      xyz="0 0 1" />
    <limit
      lower="-2.8798"
      upper="2.8798"
      effort="40"
      velocity="20.944" />
  </joint>
  <link
    name="right_arm_link2">
    <inertial>
      <origin
        xyz="-0.23622 -0.016354 0.00013181"
        rpy="0 0 0" />
      <mass
        value="1.3" />
      <inertia
        ixx="0.00060639"
        ixy="-0.00041823"
        ixz="-0.00014959"
        iyy="0.0075936"
        iyz="-8.0946E-06"
        izz="0.0075712" />
    </inertial>
    <visual>
      <origin
        xyz="0 0 0"
        rpy="0 0 0" />
      <geometry>
        <mesh
          filename="package://R1/meshes/right_arm_link2.STL" />
      </geometry>
      <material
        name="">
        <color
          rgba="0.79216 0.81961 0.93333 1" />
      </material>
    </visual>
    <collision>
      <origin
        xyz="0 0 0"
        rpy="0 0 0" />
      <geometry>
        <mesh
          filename="package://R1/meshes/right_arm_link2.STL" />
      </geometry>
    </collision>
  </link>
  <joint
    name="right_arm_joint2"
    type="revolute">
    <origin
      xyz="0 0.00087053 0.11185"
      rpy="-1.5786 0 -0.00054696" />
    <parent
      link="right_arm_link1" />
    <child
      link="right_arm_link2" />
    <axis
      xyz="0 0 1" />
    <limit
      lower="0"
      upper="3.2289"
      effort="40"
      velocity="20.944" />
  </joint>
  <link
    name="right_arm_link3">
    <inertial>
      <origin
        xyz="0.045115 -0.054616 0.00045605"
        rpy="0 0 0" />
      <mass
        value="0.818" />
      <inertia
        ixx="0.00060107"
        ixy="0.00022466"
        ixz="7.1151E-06"
        iyy="0.0013959"
        iyz="-9.7494E-06"
        izz="0.0015027" />
    </inertial>
    <visual>
      <origin
        xyz="0 0 0"
        rpy="0 0 0" />
      <geometry>
        <mesh
          filename="package://R1/meshes/right_arm_link3.STL" />
      </geometry>
      <material
        name="">
        <color
          rgba="0.79216 0.81961 0.93333 1" />
      </material>
    </visual>
    <collision>
      <origin
        xyz="0 0 0"
        rpy="0 0 0" />
      <geometry>
        <mesh
          filename="package://R1/meshes/right_arm_link3.STL" />
      </geometry>
    </collision>
  </link>
  <joint
    name="right_arm_joint3"
    type="revolute">
    <origin
      xyz="-0.34928 -0.020001 0"
      rpy="0 0 0" />
    <parent
      link="right_arm_link2" />
    <child
      link="right_arm_link3" />
    <axis
      xyz="0 0 1" />
    <limit
      lower="-3.3161"
      upper="0"
      effort="27"
      velocity="7.5398" />
  </joint>
  <link
    name="right_arm_link4">
    <inertial>
      <origin
        xyz="-8.1603E-07 0.0023773 0.24285"
        rpy="0 0 0" />
      <mass
        value="0.816" />
      <inertia
        ixx="9.7044E-05"
        ixy="-5.3698E-09"
        ixz="2.2378E-09"
        iyy="0.00010174"
        iyz="-8.2619E-07"
        izz="8.45E-05" />
    </inertial>
    <visual>
      <origin
        xyz="0 0 0"
        rpy="0 0 0" />
      <geometry>
        <mesh
          filename="package://R1/meshes/right_arm_link4.STL" />
      </geometry>
      <material
        name="">
        <color
          rgba="1 1 1 1" />
      </material>
    </visual>
    <collision>
      <origin
        xyz="0 0 0"
        rpy="0 0 0" />
      <geometry>
        <mesh
          filename="package://R1/meshes/right_arm_link4.STL" />
      </geometry>
    </collision>
  </link>
  <joint
    name="right_arm_joint4"
    type="revolute">
    <origin
      xyz="0.02735 -0.069767 0"
      rpy="0 -1.5708 3.1416" />
    <parent
      link="right_arm_link3" />
    <child
      link="right_arm_link4" />
    <axis
      xyz="0 0 1" />
    <limit
      lower="-2.8798"
      upper="2.8798"
      effort="7"
      velocity="25.133" />
  </joint>
  <link
    name="right_arm_link5">
    <inertial>
      <origin
        xyz="0.054309 -2.4377E-05 0.0011809"
        rpy="0 0 0" />
      <mass
        value="0.801" />
      <inertia
        ixx="8.4E-05"
        ixy="6.8153E-08"
        ixz="1.6234E-05"
        iyy="0.00011332"
        iyz="-1.104E-07"
        izz="9.8499E-05" />
    </inertial>
    <visual>
      <origin
        xyz="0 0 0"
        rpy="0 0 0" />
      <geometry>
        <mesh
          filename="package://R1/meshes/right_arm_link5.STL" />
      </geometry>
      <material
        name="">
        <color
          rgba="1 1 1 1" />
      </material>
    </visual>
    <collision>
      <origin
        xyz="0 0 0"
        rpy="0 0 0" />
      <geometry>
        <mesh
          filename="package://R1/meshes/right_arm_link5.STL" />
      </geometry>
    </collision>
  </link>
  <joint
    name="right_arm_joint5"
    type="revolute">
    <origin
      xyz="0 0.0025 0.2463"
      rpy="-1.5708 -1.5703 0.0077846" />
    <parent
      link="right_arm_link4" />
    <child
      link="right_arm_link5" />
    <axis
      xyz="0 0 1" />
    <limit
      lower="-1.6581"
      upper="1.6581"
      effort="7"
      velocity="25.133" />
  </joint>
  <link
    name="right_arm_link6">
    <inertial>
      <origin
        xyz="-2.223E-08 -5.7207E-08 -0.031107"
        rpy="0 0 0" />
      <mass
        value="0.465" />
      <inertia
        ixx="0.00016512"
        ixy="-4.3557E-07"
        ixz="-5.7705E-10"
        iyy="9.864E-05"
        iyz="7.4373E-11"
        izz="0.00017588" />
    </inertial>
    <visual>
      <origin
        xyz="0 0 0"
        rpy="0 0 0" />
      <geometry>
        <mesh
          filename="package://R1/meshes/right_arm_link6.STL" />
      </geometry>
      <material
        name="">
        <color
          rgba="0.82353 0.82353 1 1" />
      </material>
    </visual>
    <collision>
      <origin
        xyz="0 0 0"
        rpy="0 0 0" />
      <geometry>
        <mesh
          filename="package://R1/meshes/right_arm_link6.STL" />
      </geometry>
    </collision>
  </link>
  <joint
    name="right_arm_joint6"
    type="revolute">
    <origin
      xyz="0.16215 -0.00010784 -0.0024999"
      rpy="1.5708 0 1.5703" />
    <parent
      link="right_arm_link5" />
    <child
      link="right_arm_link6" />
    <axis
      xyz="0 0 1" />
    <limit
      lower="-2.8798"
      upper="2.8798"
      effort="7"
      velocity="25.133" />
  </joint>
  <link
    name="right_realsense_link">
    <inertial>
      <origin
        xyz="-0.017353 -0.022169 -0.0060171"
        rpy="0 0 0" />
      <mass
        value="0.042603" />
      <inertia
        ixx="2.5513E-05"
        ixy="-1.2797E-06"
        ixz="1.4268E-06"
        iyy="6.965E-06"
        iyz="2.6612E-06"
        izz="2.3281E-05" />
    </inertial>
    <visual>
      <origin
        xyz="0 0 0"
        rpy="0 0 0" />
      <geometry>
        <mesh
          filename="package://R1/meshes/right_realsense_link.STL" />
      </geometry>
      <material
        name="">
        <color
          rgba="0.8 0.8 0.8 1" />
      </material>
    </visual>
    <collision>
      <origin
        xyz="0 0 0"
        rpy="0 0 0" />
      <geometry>
        <mesh
          filename="package://R1/meshes/right_realsense_link.STL" />
      </geometry>
    </collision>
  </link>
  <joint
    name="right_realsense_axis"
    type="fixed">
    <origin
      xyz="0.050549 -0.0021066 -0.0051378"
      rpy="0 -1.1345 -3.1338" />
    <parent
      link="right_arm_link6" />
    <child
      link="right_realsense_link" />
    <axis
      xyz="0 0 0" />
  </joint>
  <link
    name="right_gripper_link1">
    <inertial>
      <origin
        xyz="-0.019593 -0.0055293 -0.015071"
        rpy="0 0 0" />
      <mass
        value="0.057" />
      <inertia
        ixx="2.4056E-06"
        ixy="-4.5884E-08"
        ixz="3.9934E-07"
        iyy="6.4839E-06"
        iyz="-6.8181E-08"
        izz="5.7118E-06" />
    </inertial>
    <visual>
      <origin
        xyz="0 0 0"
        rpy="0 0 0" />
      <geometry>
        <mesh
          filename="package://R1/meshes/right_gripper_link1.STL" />
      </geometry>
      <material
        name="">
        <color
          rgba="0.82353 0.82353 1 1" />
      </material>
    </visual>
    <collision>
      <origin
        xyz="0 0 0"
        rpy="0 0 0" />
      <geometry>
        <mesh
          filename="package://R1/meshes/right_gripper_link1.STL" />
      </geometry>
    </collision>
  </link>
  <joint
    name="right_gripper_axis1"
    type="prismatic">
    <origin
      xyz="-1.5963E-05 0.013454 0.03689"
      rpy="-1.5745 -1.5703 0.0037081" />
    <parent
      link="right_arm_link6" />
    <child
      link="right_gripper_link1" />
    <axis
      xyz="0 0 1" />
    <limit
      lower="0"
      upper="0.05"
      effort="100"
      velocity="0.25" />
  </joint>
  <link
    name="right_gripper_link2">
    <inertial>
      <origin
        xyz="-0.019586 -0.0055507 -0.015071"
        rpy="0 0 0" />
      <mass
        value="0.057" />
      <inertia
        ixx="2.4057E-06"
        ixy="-5.033E-08"
        ixz="3.9941E-07"
        iyy="6.4838E-06"
        iyz="-6.7746E-08"
        izz="5.7118E-06" />
    </inertial>
    <visual>
      <origin
        xyz="0 0 0"
        rpy="0 0 0" />
      <geometry>
        <mesh
          filename="package://R1/meshes/right_gripper_link2.STL" />
      </geometry>
      <material
        name="">
        <color
          rgba="0.82353 0.82353 1 1" />
      </material>
    </visual>
    <collision>
      <origin
        xyz="0 0 0"
        rpy="0 0 0" />
      <geometry>
        <mesh
          filename="package://R1/meshes/right_gripper_link2.STL" />
      </geometry>
    </collision>
  </link>
  <joint
    name="right_gripper_axis2"
    type="prismatic">
    <origin
      xyz="1.5816E-05 -0.013454 0.03689"
      rpy="1.5671 -1.5703 0.0037081" />
    <parent
      link="right_arm_link6" />
    <child
      link="right_gripper_link2" />
    <axis
      xyz="0 0 1" />
    <limit
      lower="0"
      upper="0.05"
      effort="100"
      velocity="0.25" />
  </joint>
</robot>